<?xml version="1.0" ?>
<robot name="my_robot" xmlns:xacro="http://www.ros.org/wiki/xacro">
    
    <!-- 1st link -->
  <link name="link_chassis">
    <pose>0 0 0.1 0 0 0</pose>
    
    <inertial>
      <mass value="5"/>
      <origin xyz="0 0 0.1" rpy="0 0 0"/>
      <inertia ixx="0.0395416666667" ixy="0" ixz="0" iyy="0.106208333333" iyz="0" izz="0.106208333333"/>
    </inertial>
    
    <collision name="collision_chassis">
      <geometry>
        <box size="1 1 2"/>
      </geometry>
    </collision>
    
    <visual>
      <origin rpy="0 0 0" xyz="0 0 0"/>
      <geometry>
        <box size="1 1 2"/>
      </geometry>
    </visual>
  </link>
  
  <joint name="joint1" type="continuous">
    <origin xyz="0.6 0 0.5" rpy="0 0 0"/>
    <parent link="link_chassis"/>
    <child link="link_arm"/>
  </joint>
  
  <!-- 2nd link -->
  <link name="link_arm">
    <pose>0 0 0 0 0 0</pose>
    
    <inertial>
      <mass value="0.5"/>
      <origin xyz="0 0 0" rpy="0 0 0"/>
      <inertia ixx="0.0395416666667" ixy="0" ixz="0" iyy="0.106208333333" iyz="0" izz="0.106208333333"/>
    </inertial>
    
    <collision name="collision_chassis">
      <geometry>
        <box size="0.2 0.2 1"/>
      </geometry>
    </collision>
    
    <visual>
      <origin xyz="0 0 0" rpy="0 0 0"/>
      <geometry>
        <box size="0.2 0.2 1"/>
      </geometry>
    </visual>
  </link>
 
</robot>
